{
  "Header": {
    "Original": "CVE-2019-16227 (An issue was discovered in py-lmdb 0.97. For certain values of mn_flag ...)",
    "Line": 279273,
    "ID": "CVE-2019-16227",
    "Description": "(An issue was discovered in py-lmdb 0.97. For certain values of mn_flag ...)"
  },
  "Annotations": [
    {
      "Original": "- py-lmdb \u003cunfixed\u003e (unimportant)",
      "Line": 279274,
      "Type": "package",
      "Package": "py-lmdb",
      "Kind": "unfixed",
      "Severity": "unimportant"
    },
    {
      "Original": "NOTE: https://github.com/jnwatson/py-lmdb/issues/210",
      "Line": 279275,
      "Type": "NOTE",
      "Description": "https://github.com/jnwatson/py-lmdb/issues/210"
    },
    {
      "Original": "NOTE: No real security issue in py-lmdb and disputed (MITRE contacted). If at all",
      "Line": 279276,
      "Type": "NOTE",
      "Description": "No real security issue in py-lmdb and disputed (MITRE contacted). If at all"
    },
    {
      "Original": "NOTE: then issues in underlying library but cf. https://github.com/jnwatson/py-lmdb/issues/210#issuecomment-531015023",
      "Line": 279277,
      "Type": "NOTE",
      "Description": "then issues in underlying library but cf. https://github.com/jnwatson/py-lmdb/issues/210#issuecomment-531015023"
    }
  ]
}