{
  "Header": {
    "Original": "CVE-2021-33571 (In Django 2.2 before 2.2.24, 3.x before 3.1.12, and 3.2 before 3.2.4,  ...)",
    "Line": 152069,
    "ID": "CVE-2021-33571",
    "Description": "(In Django 2.2 before 2.2.24, 3.x before 3.1.12, and 3.2 before 3.2.4,  ...)"
  },
  "Annotations": [
    {
      "Original": "{DLA-2676-1}",
      "Line": 152070,
      "Type": "xref",
      "Bugs": [
        "DLA-2676-1"
      ]
    },
    {
      "Original": "- python-django 2:2.2.24-1 (bug #989394)",
      "Line": 152071,
      "Type": "package",
      "Package": "python-django",
      "Kind": "fixed",
      "Version": "2:2.2.24-1",
      "BugNo": 989394
    },
    {
      "Original": "[buster] - python-django \u003cno-dsa\u003e (Minor issue)",
      "Line": 152072,
      "Type": "package",
      "Release": "buster",
      "Package": "python-django",
      "Kind": "no-dsa",
      "Description": "Minor issue"
    },
    {
      "Original": "NOTE: https://www.openwall.com/lists/oss-security/2021/06/02/1",
      "Line": 152073,
      "Type": "NOTE",
      "Description": "https://www.openwall.com/lists/oss-security/2021/06/02/1"
    },
    {
      "Original": "NOTE: https://github.com/django/django/commit/e1d787f1b36d13b95187f8f425425ae1b98da188 (main)",
      "Line": 152074,
      "Type": "NOTE",
      "Description": "https://github.com/django/django/commit/e1d787f1b36d13b95187f8f425425ae1b98da188 (main)"
    },
    {
      "Original": "NOTE: https://github.com/django/django/commit/f27c38ab5d90f68c9dd60cabef248a570c0be8fc (2.2.24)",
      "Line": 152075,
      "Type": "NOTE",
      "Description": "https://github.com/django/django/commit/f27c38ab5d90f68c9dd60cabef248a570c0be8fc (2.2.24)"
    }
  ]
}